<?xml version="1.0" ?>
<!-- =================================================================================== -->
<!-- |    This document was autogenerated by xacro from gripper.urdf.xacro             | -->
<!-- |    EDITING THIS FILE BY HAND IS NOT RECOMMENDED                                 | -->
<!-- =================================================================================== -->
<robot name="gripper">
  <!-- PARAMETERS TO BE SET BY HAND -->
  <!-- END OF PARAMETERS TO BE SET BY HAND -->
  <!-- PARAMETERS TO BE SET BY HAND -->
  <!-- END OF PARAMETER TO BE SET BY HAND -->
  <!-- BASE LINK -->
  <link name="gripper_base_link">
    <inertial>
      <mass value="1.5"/>
      <origin rpy="3.141592653589793 0 0" xyz="0 0 0.025"/>
      <inertia ixx="9.95e-3" ixy="2.73e-6" ixz="-14.32e-6" iyy="10.08e-3" iyz="121.38e-6" izz="5.13e-3"/>
    </inertial>
    <visual>
      <geometry>
        <mesh filename="package://gripper_description/meshes/main body visual.STL"/>
      </geometry>
    </visual>
    <collision>
      <geometry>
        <!--          <mesh filename="package://gripper_description/meshes/main body collision.STL"/>-->
        <cylinder length="0.1" radius="0.03"/>
      </geometry>
    </collision>
  </link>
  <!-- Intermediate link for prismatic joint -->
  <link name="finger_1_intermediate">
    <inertial>
      <mass value="0.1"/>
      <origin rpy="0 0 0" xyz="0 0 0"/>
      <inertia ixx="55.59e-6" ixy="-47.23e-6" ixz="1.16e-6" iyy="146.36e-6" iyz="1.00e-6" izz="154.18e-6"/>
    </inertial>
    <visual>
      <geometry>
        <mesh filename="package://gripper_description/meshes/nut visual.STL"/>
      </geometry>
    </visual>
    <collision>
      <geometry>
        <mesh filename="package://gripper_description/meshes/nut collision.STL"/>
      </geometry>
    </collision>
  </link>
  <!-- Main finger link -->
  <link name="finger_1">
    <inertial>
      <mass value="0.2"/>
      <origin rpy="0 0 0" xyz="0 0 0"/>
      <inertia ixx="283.44e-6" ixy="-567.23e-6" ixz="-6.59e-6" iyy="1.38e-3" iyz="2.40e-6" izz="1.60e-3"/>
    </inertial>
    <visual>
      <geometry>
        <mesh filename="package://gripper_description/meshes/finger platform visual.STL"/>
      </geometry>
    </visual>
    <collision>
      <geometry>
        <mesh filename="package://gripper_description/meshes/finger platform collision.STL"/>
      </geometry>
    </collision>
  </link>
  <joint name="finger_1_prismatic_joint" type="prismatic">
    <axis rpy="0 0 0" xyz="0 1 0"/>
    <parent link="gripper_base_link"/>
    <child link="finger_1_intermediate"/>
    <origin rpy="4.71238898038469                    4.71238898038469                    1.5707963267948966" xyz="0.0                    0.0                    0"/>
    <limit effort="40.0" lower="0.049" upper="0.134" velocity="0.015"/>
    <dynamics damping="1.0"/>
  </joint>
  <joint name="finger_1_revolute_joint" type="revolute">
    <axis rpy="0 0 0" xyz="0 0 1"/>
    <parent link="finger_1_intermediate"/>
    <child link="finger_1"/>
    <origin rpy="0 0 0.0" xyz="0 0 0"/>
    <limit effort="40.0" lower="-0.7" upper="0.7" velocity="0.1"/>
    <dynamics damping="1.0"/>
  </joint>
  <!-- Intermediate link for prismatic joint -->
  <link name="finger_2_intermediate">
    <inertial>
      <mass value="0.1"/>
      <origin rpy="0 0 0" xyz="0 0 0"/>
      <inertia ixx="55.59e-6" ixy="-47.23e-6" ixz="1.16e-6" iyy="146.36e-6" iyz="1.00e-6" izz="154.18e-6"/>
    </inertial>
    <visual>
      <geometry>
        <mesh filename="package://gripper_description/meshes/nut visual.STL"/>
      </geometry>
    </visual>
    <collision>
      <geometry>
        <mesh filename="package://gripper_description/meshes/nut collision.STL"/>
      </geometry>
    </collision>
  </link>
  <!-- Main finger link -->
  <link name="finger_2">
    <inertial>
      <mass value="0.2"/>
      <origin rpy="0 0 0" xyz="0 0 0"/>
      <inertia ixx="283.44e-6" ixy="-567.23e-6" ixz="-6.59e-6" iyy="1.38e-3" iyz="2.40e-6" izz="1.60e-3"/>
    </inertial>
    <visual>
      <geometry>
        <mesh filename="package://gripper_description/meshes/finger platform visual.STL"/>
      </geometry>
    </visual>
    <collision>
      <geometry>
        <mesh filename="package://gripper_description/meshes/finger platform collision.STL"/>
      </geometry>
    </collision>
  </link>
  <joint name="finger_2_prismatic_joint" type="prismatic">
    <axis rpy="0 0 0" xyz="0 1 0"/>
    <parent link="gripper_base_link"/>
    <child link="finger_2_intermediate"/>
    <origin rpy="4.71238898038469                    4.71238898038469                    -0.5235987755982987" xyz="0.0                    -0.0                    0"/>
    <limit effort="40.0" lower="0.049" upper="0.134" velocity="0.015"/>
    <dynamics damping="1.0"/>
  </joint>
  <joint name="finger_2_revolute_joint" type="revolute">
    <axis rpy="0 0 0" xyz="0 0 1"/>
    <parent link="finger_2_intermediate"/>
    <child link="finger_2"/>
    <origin rpy="0 0 0.0" xyz="0 0 0"/>
    <limit effort="40.0" lower="-0.7" upper="0.7" velocity="0.1"/>
    <dynamics damping="1.0"/>
  </joint>
  <!-- Intermediate link for prismatic joint -->
  <link name="finger_3_intermediate">
    <inertial>
      <mass value="0.1"/>
      <origin rpy="0 0 0" xyz="0 0 0"/>
      <inertia ixx="55.59e-6" ixy="-47.23e-6" ixz="1.16e-6" iyy="146.36e-6" iyz="1.00e-6" izz="154.18e-6"/>
    </inertial>
    <visual>
      <geometry>
        <mesh filename="package://gripper_description/meshes/nut visual.STL"/>
      </geometry>
    </visual>
    <collision>
      <geometry>
        <mesh filename="package://gripper_description/meshes/nut collision.STL"/>
      </geometry>
    </collision>
  </link>
  <!-- Main finger link -->
  <link name="finger_3">
    <inertial>
      <mass value="0.2"/>
      <origin rpy="0 0 0" xyz="0 0 0"/>
      <inertia ixx="283.44e-6" ixy="-567.23e-6" ixz="-6.59e-6" iyy="1.38e-3" iyz="2.40e-6" izz="1.60e-3"/>
    </inertial>
    <visual>
      <geometry>
        <mesh filename="package://gripper_description/meshes/finger platform visual.STL"/>
      </geometry>
    </visual>
    <collision>
      <geometry>
        <mesh filename="package://gripper_description/meshes/finger platform collision.STL"/>
      </geometry>
    </collision>
  </link>
  <joint name="finger_3_prismatic_joint" type="prismatic">
    <axis rpy="0 0 0" xyz="0 1 0"/>
    <parent link="gripper_base_link"/>
    <child link="finger_3_intermediate"/>
    <origin rpy="4.71238898038469                    4.71238898038469                    -2.617993877991494" xyz="-0.0                    -0.0                    0"/>
    <limit effort="40.0" lower="0.049" upper="0.134" velocity="0.015"/>
    <dynamics damping="1.0"/>
  </joint>
  <joint name="finger_3_revolute_joint" type="revolute">
    <axis rpy="0 0 0" xyz="0 0 1"/>
    <parent link="finger_3_intermediate"/>
    <child link="finger_3"/>
    <origin rpy="0 0 0.0" xyz="0 0 0"/>
    <limit effort="40.0" lower="-0.7" upper="0.7" velocity="0.1"/>
    <dynamics damping="1.0"/>
  </joint>
  <!-- PALM -->
  <link name="palm">
    <inertial>
      <mass value="0.05"/>
      <origin rpy="0 0 0" xyz="0 0 0"/>
      <inertia ixx="10.0e-6" ixy="0.0" ixz="0.0" iyy="10.0e-6" iyz="0.0" izz="10.0e-6"/>
    </inertial>
    <visual>
      <origin rpy="0 0 0" xyz="0 0 0"/>
      <geometry>
        <mesh filename="package://gripper_description/meshes/palm visual.STL"/>
      </geometry>
    </visual>
    <collision>
      <geometry>
        <mesh filename="package://gripper_description/meshes/palm collision.STL"/>
      </geometry>
    </collision>
  </link>
  <joint name="palm_prismatic_joint" type="prismatic">
    <axis rpy="0 0 0" xyz="1 0 0"/>
    <parent link="gripper_base_link"/>
    <child link="palm"/>
    <origin rpy="0 -1.5707963267948966 0" xyz="0 0 0"/>
    <limit effort="40.0" lower="0.0" upper="0.165" velocity="0.036"/>
    <dynamics damping="1.0"/>
  </joint>
  <!-- attach gripper to the ground for gazebo -->
  <link name="world"/>
  <joint name="world_to_base" type="fixed">
    <origin rpy="3.141592653589793 0 0" xyz="0 0 1"/>
    <parent link="world"/>
    <child link="gripper_base_link"/>
  </joint>
</robot>

