<?xml version="1.0" ?>
<!-- =================================================================================== -->
<!-- |    This document was autogenerated by xacro from gripper.urdf.xacro             | -->
<!-- |    EDITING THIS FILE BY HAND IS NOT RECOMMENDED                                 | -->
<!-- =================================================================================== -->
<robot name="gripper">
  <!-- PARAMETERS TO BE SET BY HAND -->
  <!-- END OF PARAMETERS TO BE SET BY HAND -->
  <!-- PARAMETERS TO BE SET BY HAND -->
  <!-- END OF PARAMETER TO BE SET BY HAND -->
  <!-- BASE LINK -->
  <link name="gripper_base_link">
    <inertial>
      <mass value="1.5"/>
      <origin rpy="3.141592653589793 0 0" xyz="0 0 0.025"/>
      <inertia ixx="9.95e-3" ixy="2.73e-6" ixz="-14.32e-6" iyy="10.08e-3" iyz="121.38e-6" izz="5.13e-3"/>
    </inertial>
    <visual>
      <geometry>
        <mesh filename="package://gripper_description/meshes/main body visual.STL"/>
      </geometry>
    </visual>
    <collision>
      <geometry>
        <!--          <mesh filename="package://gripper_description/meshes/main body collision.STL"/>-->
        <cylinder length="0.1" radius="0.03"/>
      </geometry>
    </collision>
  </link>
  <!-- Intermediate link for prismatic joint -->
  <link name="finger_1_intermediate">
    <inertial>
      <mass value="0.1"/>
      <origin rpy="0 0 0" xyz="0 0 0"/>
      <inertia ixx="55.59e-6" ixy="-47.23e-6" ixz="1.16e-6" iyy="146.36e-6" iyz="1.00e-6" izz="154.18e-6"/>
    </inertial>
    <visual>
      <geometry>
        <mesh filename="package://gripper_description/meshes/nut visual.STL"/>
      </geometry>
    </visual>
    <collision>
      <geometry>
        <mesh filename="package://gripper_description/meshes/nut collision.STL"/>
      </geometry>
    </collision>
  </link>
  <!-- Main finger link -->
  <link name="finger_1">
    <inertial>
      <mass value="0.1"/>
      <origin rpy="0 0 0" xyz="0 0 0"/>
      <inertia ixx="55.59e-6" ixy="-47.23e-6" ixz="1.16e-6" iyy="146.36e-6" iyz="1.00e-6" izz="154.18e-6"/>
    </inertial>
    <visual>
      <geometry>
        <mesh filename="package://gripper_description/meshes/platform only visual.STL"/>
      </geometry>
    </visual>
    <collision>
      <geometry>
        <mesh filename="package://gripper_description/meshes/platform only collision.STL"/>
      </geometry>
    </collision>
  </link>
  <joint name="finger_1_prismatic_joint" type="prismatic">
    <axis rpy="0 0 0" xyz="0 1 0"/>
    <parent link="gripper_base_link"/>
    <child link="finger_1_intermediate"/>
    <origin rpy="4.71238898038469                    4.71238898038469                    1.5707963267948966" xyz="0.0                    0.0                    0"/>
    <limit effort="40.0" lower="0.049" upper="0.134" velocity="0.015"/>
    <dynamics damping="1.0"/>
  </joint>
  <joint name="finger_1_revolute_joint" type="revolute">
    <axis rpy="0 0 0" xyz="0 0 1"/>
    <parent link="finger_1_intermediate"/>
    <child link="finger_1"/>
    <origin rpy="0 0 0.0" xyz="0 0 0"/>
    <limit effort="40.0" lower="-0.7" upper="0.7" velocity="0.1"/>
    <dynamics damping="1.0"/>
  </joint>
  <!-- Intermediate link for prismatic joint -->
  <link name="finger_2_intermediate">
    <inertial>
      <mass value="0.1"/>
      <origin rpy="0 0 0" xyz="0 0 0"/>
      <inertia ixx="55.59e-6" ixy="-47.23e-6" ixz="1.16e-6" iyy="146.36e-6" iyz="1.00e-6" izz="154.18e-6"/>
    </inertial>
    <visual>
      <geometry>
        <mesh filename="package://gripper_description/meshes/nut visual.STL"/>
      </geometry>
    </visual>
    <collision>
      <geometry>
        <mesh filename="package://gripper_description/meshes/nut collision.STL"/>
      </geometry>
    </collision>
  </link>
  <!-- Main finger link -->
  <link name="finger_2">
    <inertial>
      <mass value="0.1"/>
      <origin rpy="0 0 0" xyz="0 0 0"/>
      <inertia ixx="55.59e-6" ixy="-47.23e-6" ixz="1.16e-6" iyy="146.36e-6" iyz="1.00e-6" izz="154.18e-6"/>
    </inertial>
    <visual>
      <geometry>
        <mesh filename="package://gripper_description/meshes/platform only visual.STL"/>
      </geometry>
    </visual>
    <collision>
      <geometry>
        <mesh filename="package://gripper_description/meshes/platform only collision.STL"/>
      </geometry>
    </collision>
  </link>
  <joint name="finger_2_prismatic_joint" type="prismatic">
    <axis rpy="0 0 0" xyz="0 1 0"/>
    <parent link="gripper_base_link"/>
    <child link="finger_2_intermediate"/>
    <origin rpy="4.71238898038469                    4.71238898038469                    -0.5235987755982987" xyz="0.0                    -0.0                    0"/>
    <limit effort="40.0" lower="0.049" upper="0.134" velocity="0.015"/>
    <dynamics damping="1.0"/>
  </joint>
  <joint name="finger_2_revolute_joint" type="revolute">
    <axis rpy="0 0 0" xyz="0 0 1"/>
    <parent link="finger_2_intermediate"/>
    <child link="finger_2"/>
    <origin rpy="0 0 0.0" xyz="0 0 0"/>
    <limit effort="40.0" lower="-0.7" upper="0.7" velocity="0.1"/>
    <dynamics damping="1.0"/>
  </joint>
  <!-- Intermediate link for prismatic joint -->
  <link name="finger_3_intermediate">
    <inertial>
      <mass value="0.1"/>
      <origin rpy="0 0 0" xyz="0 0 0"/>
      <inertia ixx="55.59e-6" ixy="-47.23e-6" ixz="1.16e-6" iyy="146.36e-6" iyz="1.00e-6" izz="154.18e-6"/>
    </inertial>
    <visual>
      <geometry>
        <mesh filename="package://gripper_description/meshes/nut visual.STL"/>
      </geometry>
    </visual>
    <collision>
      <geometry>
        <mesh filename="package://gripper_description/meshes/nut collision.STL"/>
      </geometry>
    </collision>
  </link>
  <!-- Main finger link -->
  <link name="finger_3">
    <inertial>
      <mass value="0.1"/>
      <origin rpy="0 0 0" xyz="0 0 0"/>
      <inertia ixx="55.59e-6" ixy="-47.23e-6" ixz="1.16e-6" iyy="146.36e-6" iyz="1.00e-6" izz="154.18e-6"/>
    </inertial>
    <visual>
      <geometry>
        <mesh filename="package://gripper_description/meshes/platform only visual.STL"/>
      </geometry>
    </visual>
    <collision>
      <geometry>
        <mesh filename="package://gripper_description/meshes/platform only collision.STL"/>
      </geometry>
    </collision>
  </link>
  <joint name="finger_3_prismatic_joint" type="prismatic">
    <axis rpy="0 0 0" xyz="0 1 0"/>
    <parent link="gripper_base_link"/>
    <child link="finger_3_intermediate"/>
    <origin rpy="4.71238898038469                    4.71238898038469                    -2.617993877991494" xyz="-0.0                    -0.0                    0"/>
    <limit effort="40.0" lower="0.049" upper="0.134" velocity="0.015"/>
    <dynamics damping="1.0"/>
  </joint>
  <joint name="finger_3_revolute_joint" type="revolute">
    <axis rpy="0 0 0" xyz="0 0 1"/>
    <parent link="finger_3_intermediate"/>
    <child link="finger_3"/>
    <origin rpy="0 0 0.0" xyz="0 0 0"/>
    <limit effort="40.0" lower="-0.7" upper="0.7" velocity="0.1"/>
    <dynamics damping="1.0"/>
  </joint>
  <!-- PALM -->
  <link name="palm">
    <inertial>
      <mass value="0.05"/>
      <origin rpy="0 0 0" xyz="0 0 0"/>
      <inertia ixx="10.0e-6" ixy="0.0" ixz="0.0" iyy="10.0e-6" iyz="0.0" izz="10.0e-6"/>
    </inertial>
    <visual>
      <origin rpy="0 0 0" xyz="0 0 0"/>
      <geometry>
        <mesh filename="package://gripper_description/meshes/palm visual.STL"/>
      </geometry>
    </visual>
    <collision>
      <geometry>
        <mesh filename="package://gripper_description/meshes/palm collision.STL"/>
      </geometry>
    </collision>
  </link>
  <joint name="palm_prismatic_joint" type="prismatic">
    <axis rpy="0 0 0" xyz="1 0 0"/>
    <parent link="gripper_base_link"/>
    <child link="palm"/>
    <origin rpy="0 -1.5707963267948966 0" xyz="0 0 0"/>
    <limit effort="40.0" lower="0.0" upper="0.165" velocity="0.036"/>
    <dynamics damping="1.0"/>
  </joint>
  <!-- PARAMETERS TO BE SET BY HAND -->
  <!-- END OF PARAMETERS TO BE SET BY HAND -->
  <joint name="finger_1_segment_joint_0" type="revolute">
    <origin rpy="1.5707963267948966 0 0" xyz="0.129 -0.007 0"/>
    <parent link="finger_1"/>
    <child link="finger_1_segment_link_1"/>
    <axis rpy="0 0 0" xyz="0 1 0"/>
    <limit effort="1000.0" lower="-1.0" upper="1.0" velocity="1.0"/>
    <dynamics damping="0.01" friction="0.0"/>
  </joint>
  <!-- END TESTING OF BASE JOINT (rather than fixed) -->
  <link name="finger_1_segment_link_1">
    <inertial>
      <mass value="0.013055555555555555"/>
      <inertia ixx="8.538442129629629e-07" ixy="0.00" ixz="0.00" iyy="9.61412199074074e-06" iyz="0.00" izz="1.0466203703703703e-05"/>
    </inertial>
    <visual>
      <origin rpy="0 0 0" xyz="0.0235 0 0"/>
      <geometry>
        <box size="0.047 0.028 0.0009"/>
      </geometry>
    </visual>
    <collision>
      <origin rpy="0 0 0" xyz="0.0235 0 0"/>
      <geometry>
        <box size="0.047 0.028 0.0009"/>
      </geometry>
    </collision>
  </link>
  <gazebo reference="finger_1_segment_link_1">
    <material>Gazebo/Orange</material>
    <mu1>0.1</mu1>
    <mu2>0.1</mu2>
    <maxVel>0.0</maxVel>
    <minDepth>0.001</minDepth>
    <!-- <kp>100</kp>
        <kd>1</kd> -->
  </gazebo>
  <link name="finger_1_segment_link_2">
    <inertial>
      <mass value="0.013055555555555555"/>
      <inertia ixx="8.538442129629629e-07" ixy="0.00" ixz="0.00" iyy="9.61412199074074e-06" iyz="0.00" izz="1.0466203703703703e-05"/>
    </inertial>
    <visual>
      <origin rpy="0 0 0" xyz="0.0235 0 0"/>
      <geometry>
        <box size="0.047 0.028 0.0009"/>
      </geometry>
    </visual>
    <collision>
      <origin rpy="0 0 0" xyz="0.0235 0 0"/>
      <geometry>
        <box size="0.047 0.028 0.0009"/>
      </geometry>
    </collision>
  </link>
  <gazebo reference="finger_1_segment_link_2">
    <material>Gazebo/Orange</material>
    <mu1>0.1</mu1>
    <mu2>0.1</mu2>
    <maxVel>0.0</maxVel>
    <minDepth>0.001</minDepth>
    <!-- <kp>100</kp>
        <kd>1</kd> -->
  </gazebo>
  <!-- bending joint -->
  <joint name="finger_1_segment_joint_1" type="revolute">
    <axis rpy="0 0 0" xyz="0 1 0"/>
    <parent link="finger_1_segment_link_1"/>
    <child link="finger_1_segment_link_2"/>
    <origin rpy="0 0 0" xyz="0.047 0 0"/>
    <limit effort="1000.0" lower="-1.0" upper="1.0" velocity="1.0"/>
    <dynamics damping="0.01" friction="0.0"/>
  </joint>
  <gazebo reference="finger_1_segment_joint_1">
    <provideFeedback>1</provideFeedback>
    <springReference>0.0</springReference>
    <implicitSpringDamper>1</implicitSpringDamper>
    <springStiffness>3.0</springStiffness>
  </gazebo>
  <!-- set transmission for gazebo ROS controllers-->
  <transmission name="finger_1_segment_tran_1">
    <type>transmission_interface/SimpleTransmission</type>
    <joint name="finger_1_segment_joint_1">
      <hardwareInterface>hardware_interface/EffortJointInterface</hardwareInterface>
    </joint>
    <actuator name="finger_1_segment_motor_1">
      <hardwareInterface>hardware_interface/EffortJointInterface</hardwareInterface>
      <mechanicalReduction>1</mechanicalReduction>
    </actuator>
  </transmission>
  <link name="finger_1_segment_link_3">
    <inertial>
      <mass value="0.013055555555555555"/>
      <inertia ixx="8.538442129629629e-07" ixy="0.00" ixz="0.00" iyy="9.61412199074074e-06" iyz="0.00" izz="1.0466203703703703e-05"/>
    </inertial>
    <visual>
      <origin rpy="0 0 0" xyz="0.0235 0 0"/>
      <geometry>
        <box size="0.047 0.028 0.0009"/>
      </geometry>
    </visual>
    <collision>
      <origin rpy="0 0 0" xyz="0.0235 0 0"/>
      <geometry>
        <box size="0.047 0.028 0.0009"/>
      </geometry>
    </collision>
  </link>
  <gazebo reference="finger_1_segment_link_3">
    <material>Gazebo/Orange</material>
    <mu1>0.1</mu1>
    <mu2>0.1</mu2>
    <maxVel>0.0</maxVel>
    <minDepth>0.001</minDepth>
    <!-- <kp>100</kp>
        <kd>1</kd> -->
  </gazebo>
  <!-- bending joint -->
  <joint name="finger_1_segment_joint_2" type="revolute">
    <axis rpy="0 0 0" xyz="0 1 0"/>
    <parent link="finger_1_segment_link_2"/>
    <child link="finger_1_segment_link_3"/>
    <origin rpy="0 0 0" xyz="0.047 0 0"/>
    <limit effort="1000.0" lower="-1.0" upper="1.0" velocity="1.0"/>
    <dynamics damping="0.01" friction="0.0"/>
  </joint>
  <gazebo reference="finger_1_segment_joint_2">
    <provideFeedback>1</provideFeedback>
    <springReference>0.0</springReference>
    <implicitSpringDamper>1</implicitSpringDamper>
    <springStiffness>3.0</springStiffness>
  </gazebo>
  <!-- set transmission for gazebo ROS controllers-->
  <transmission name="finger_1_segment_tran_2">
    <type>transmission_interface/SimpleTransmission</type>
    <joint name="finger_1_segment_joint_2">
      <hardwareInterface>hardware_interface/EffortJointInterface</hardwareInterface>
    </joint>
    <actuator name="finger_1_segment_motor_2">
      <hardwareInterface>hardware_interface/EffortJointInterface</hardwareInterface>
      <mechanicalReduction>1</mechanicalReduction>
    </actuator>
  </transmission>
  <link name="finger_1_segment_link_4">
    <inertial>
      <mass value="0.013055555555555555"/>
      <inertia ixx="8.538442129629629e-07" ixy="0.00" ixz="0.00" iyy="9.61412199074074e-06" iyz="0.00" izz="1.0466203703703703e-05"/>
    </inertial>
    <visual>
      <origin rpy="0 0 0" xyz="0.0235 0 0"/>
      <geometry>
        <box size="0.047 0.028 0.0009"/>
      </geometry>
    </visual>
    <collision>
      <origin rpy="0 0 0" xyz="0.0235 0 0"/>
      <geometry>
        <box size="0.047 0.028 0.0009"/>
      </geometry>
    </collision>
  </link>
  <gazebo reference="finger_1_segment_link_4">
    <material>Gazebo/Orange</material>
    <mu1>0.1</mu1>
    <mu2>0.1</mu2>
    <maxVel>0.0</maxVel>
    <minDepth>0.001</minDepth>
    <!-- <kp>100</kp>
        <kd>1</kd> -->
  </gazebo>
  <!-- bending joint -->
  <joint name="finger_1_segment_joint_3" type="revolute">
    <axis rpy="0 0 0" xyz="0 1 0"/>
    <parent link="finger_1_segment_link_3"/>
    <child link="finger_1_segment_link_4"/>
    <origin rpy="0 0 0" xyz="0.047 0 0"/>
    <limit effort="1000.0" lower="-1.0" upper="1.0" velocity="1.0"/>
    <dynamics damping="0.01" friction="0.0"/>
  </joint>
  <gazebo reference="finger_1_segment_joint_3">
    <provideFeedback>1</provideFeedback>
    <springReference>0.0</springReference>
    <implicitSpringDamper>1</implicitSpringDamper>
    <springStiffness>3.0</springStiffness>
  </gazebo>
  <!-- set transmission for gazebo ROS controllers-->
  <transmission name="finger_1_segment_tran_3">
    <type>transmission_interface/SimpleTransmission</type>
    <joint name="finger_1_segment_joint_3">
      <hardwareInterface>hardware_interface/EffortJointInterface</hardwareInterface>
    </joint>
    <actuator name="finger_1_segment_motor_3">
      <hardwareInterface>hardware_interface/EffortJointInterface</hardwareInterface>
      <mechanicalReduction>1</mechanicalReduction>
    </actuator>
  </transmission>
  <link name="finger_1_segment_link_5">
    <inertial>
      <mass value="0.013055555555555555"/>
      <inertia ixx="8.538442129629629e-07" ixy="0.00" ixz="0.00" iyy="9.61412199074074e-06" iyz="0.00" izz="1.0466203703703703e-05"/>
    </inertial>
    <visual>
      <origin rpy="0 0 0" xyz="0.0235 0 0"/>
      <geometry>
        <box size="0.047 0.028 0.0009"/>
      </geometry>
    </visual>
    <collision>
      <origin rpy="0 0 0" xyz="0.0235 0 0"/>
      <geometry>
        <box size="0.047 0.028 0.0009"/>
      </geometry>
    </collision>
  </link>
  <gazebo reference="finger_1_segment_link_5">
    <material>Gazebo/Orange</material>
    <mu1>0.1</mu1>
    <mu2>0.1</mu2>
    <maxVel>0.0</maxVel>
    <minDepth>0.001</minDepth>
    <!-- <kp>100</kp>
        <kd>1</kd> -->
  </gazebo>
  <!-- bending joint -->
  <joint name="finger_1_segment_joint_4" type="revolute">
    <axis rpy="0 0 0" xyz="0 1 0"/>
    <parent link="finger_1_segment_link_4"/>
    <child link="finger_1_segment_link_5"/>
    <origin rpy="0 0 0" xyz="0.047 0 0"/>
    <limit effort="1000.0" lower="-1.0" upper="1.0" velocity="1.0"/>
    <dynamics damping="0.01" friction="0.0"/>
  </joint>
  <gazebo reference="finger_1_segment_joint_4">
    <provideFeedback>1</provideFeedback>
    <springReference>0.0</springReference>
    <implicitSpringDamper>1</implicitSpringDamper>
    <springStiffness>3.0</springStiffness>
  </gazebo>
  <!-- set transmission for gazebo ROS controllers-->
  <transmission name="finger_1_segment_tran_4">
    <type>transmission_interface/SimpleTransmission</type>
    <joint name="finger_1_segment_joint_4">
      <hardwareInterface>hardware_interface/EffortJointInterface</hardwareInterface>
    </joint>
    <actuator name="finger_1_segment_motor_4">
      <hardwareInterface>hardware_interface/EffortJointInterface</hardwareInterface>
      <mechanicalReduction>1</mechanicalReduction>
    </actuator>
  </transmission>
  <!-- Add the finger hook link -->
  <link name="finger_1_finger_hook_link">
    <inertial>
      <mass value="0.009722222222222222"/>
      <inertia ixx="6.358414351851852e-07" ixy="0.00" ixz="0.00" iyy="3.970563657407408e-06" iyz="0.00" izz="4.605092592592593e-06"/>
    </inertial>
    <visual>
      <origin rpy="0 0 0" xyz="0.0175 0 0"/>
      <geometry>
        <box size="0.035 0.028 0.0009"/>
      </geometry>
    </visual>
    <collision>
      <origin rpy="0 0 0" xyz="0.0175 0 0"/>
      <geometry>
        <box size="0.035 0.028 0.0009"/>
      </geometry>
    </collision>
  </link>
  <gazebo reference="finger_1_finger_hook_link">
    <material>Gazebo/Orange</material>
    <mu1>0.1</mu1>
    <mu2>0.1</mu2>
    <maxVel>0.0</maxVel>
    <minDepth>0.001</minDepth>
    <!-- <kp>100</kp>
        <kd>1</kd> -->
  </gazebo>
  <joint name="finger_1_finger_hook_joint" type="fixed">
    <parent link="finger_1_segment_link_5"/>
    <child link="finger_1_finger_hook_link"/>
    <origin rpy="0 -1.5707963267948502 0" xyz="0.047 0 0"/>
  </joint>
  <!-- PARAMETERS TO BE SET BY HAND -->
  <!-- END OF PARAMETERS TO BE SET BY HAND -->
  <joint name="finger_2_segment_joint_0" type="revolute">
    <origin rpy="1.5707963267948966 0 0" xyz="0.129 -0.007 0"/>
    <parent link="finger_2"/>
    <child link="finger_2_segment_link_1"/>
    <axis rpy="0 0 0" xyz="0 1 0"/>
    <limit effort="1000.0" lower="-1.0" upper="1.0" velocity="1.0"/>
    <dynamics damping="0.01" friction="0.0"/>
  </joint>
  <!-- END TESTING OF BASE JOINT (rather than fixed) -->
  <link name="finger_2_segment_link_1">
    <inertial>
      <mass value="0.013055555555555555"/>
      <inertia ixx="8.538442129629629e-07" ixy="0.00" ixz="0.00" iyy="9.61412199074074e-06" iyz="0.00" izz="1.0466203703703703e-05"/>
    </inertial>
    <visual>
      <origin rpy="0 0 0" xyz="0.0235 0 0"/>
      <geometry>
        <box size="0.047 0.028 0.0009"/>
      </geometry>
    </visual>
    <collision>
      <origin rpy="0 0 0" xyz="0.0235 0 0"/>
      <geometry>
        <box size="0.047 0.028 0.0009"/>
      </geometry>
    </collision>
  </link>
  <gazebo reference="finger_2_segment_link_1">
    <material>Gazebo/Orange</material>
    <mu1>0.1</mu1>
    <mu2>0.1</mu2>
    <maxVel>0.0</maxVel>
    <minDepth>0.001</minDepth>
    <!-- <kp>100</kp>
        <kd>1</kd> -->
  </gazebo>
  <link name="finger_2_segment_link_2">
    <inertial>
      <mass value="0.013055555555555555"/>
      <inertia ixx="8.538442129629629e-07" ixy="0.00" ixz="0.00" iyy="9.61412199074074e-06" iyz="0.00" izz="1.0466203703703703e-05"/>
    </inertial>
    <visual>
      <origin rpy="0 0 0" xyz="0.0235 0 0"/>
      <geometry>
        <box size="0.047 0.028 0.0009"/>
      </geometry>
    </visual>
    <collision>
      <origin rpy="0 0 0" xyz="0.0235 0 0"/>
      <geometry>
        <box size="0.047 0.028 0.0009"/>
      </geometry>
    </collision>
  </link>
  <gazebo reference="finger_2_segment_link_2">
    <material>Gazebo/Orange</material>
    <mu1>0.1</mu1>
    <mu2>0.1</mu2>
    <maxVel>0.0</maxVel>
    <minDepth>0.001</minDepth>
    <!-- <kp>100</kp>
        <kd>1</kd> -->
  </gazebo>
  <!-- bending joint -->
  <joint name="finger_2_segment_joint_1" type="revolute">
    <axis rpy="0 0 0" xyz="0 1 0"/>
    <parent link="finger_2_segment_link_1"/>
    <child link="finger_2_segment_link_2"/>
    <origin rpy="0 0 0" xyz="0.047 0 0"/>
    <limit effort="1000.0" lower="-1.0" upper="1.0" velocity="1.0"/>
    <dynamics damping="0.01" friction="0.0"/>
  </joint>
  <gazebo reference="finger_2_segment_joint_1">
    <provideFeedback>1</provideFeedback>
    <springReference>0.0</springReference>
    <implicitSpringDamper>1</implicitSpringDamper>
    <springStiffness>3.0</springStiffness>
  </gazebo>
  <!-- set transmission for gazebo ROS controllers-->
  <transmission name="finger_2_segment_tran_1">
    <type>transmission_interface/SimpleTransmission</type>
    <joint name="finger_2_segment_joint_1">
      <hardwareInterface>hardware_interface/EffortJointInterface</hardwareInterface>
    </joint>
    <actuator name="finger_2_segment_motor_1">
      <hardwareInterface>hardware_interface/EffortJointInterface</hardwareInterface>
      <mechanicalReduction>1</mechanicalReduction>
    </actuator>
  </transmission>
  <link name="finger_2_segment_link_3">
    <inertial>
      <mass value="0.013055555555555555"/>
      <inertia ixx="8.538442129629629e-07" ixy="0.00" ixz="0.00" iyy="9.61412199074074e-06" iyz="0.00" izz="1.0466203703703703e-05"/>
    </inertial>
    <visual>
      <origin rpy="0 0 0" xyz="0.0235 0 0"/>
      <geometry>
        <box size="0.047 0.028 0.0009"/>
      </geometry>
    </visual>
    <collision>
      <origin rpy="0 0 0" xyz="0.0235 0 0"/>
      <geometry>
        <box size="0.047 0.028 0.0009"/>
      </geometry>
    </collision>
  </link>
  <gazebo reference="finger_2_segment_link_3">
    <material>Gazebo/Orange</material>
    <mu1>0.1</mu1>
    <mu2>0.1</mu2>
    <maxVel>0.0</maxVel>
    <minDepth>0.001</minDepth>
    <!-- <kp>100</kp>
        <kd>1</kd> -->
  </gazebo>
  <!-- bending joint -->
  <joint name="finger_2_segment_joint_2" type="revolute">
    <axis rpy="0 0 0" xyz="0 1 0"/>
    <parent link="finger_2_segment_link_2"/>
    <child link="finger_2_segment_link_3"/>
    <origin rpy="0 0 0" xyz="0.047 0 0"/>
    <limit effort="1000.0" lower="-1.0" upper="1.0" velocity="1.0"/>
    <dynamics damping="0.01" friction="0.0"/>
  </joint>
  <gazebo reference="finger_2_segment_joint_2">
    <provideFeedback>1</provideFeedback>
    <springReference>0.0</springReference>
    <implicitSpringDamper>1</implicitSpringDamper>
    <springStiffness>3.0</springStiffness>
  </gazebo>
  <!-- set transmission for gazebo ROS controllers-->
  <transmission name="finger_2_segment_tran_2">
    <type>transmission_interface/SimpleTransmission</type>
    <joint name="finger_2_segment_joint_2">
      <hardwareInterface>hardware_interface/EffortJointInterface</hardwareInterface>
    </joint>
    <actuator name="finger_2_segment_motor_2">
      <hardwareInterface>hardware_interface/EffortJointInterface</hardwareInterface>
      <mechanicalReduction>1</mechanicalReduction>
    </actuator>
  </transmission>
  <link name="finger_2_segment_link_4">
    <inertial>
      <mass value="0.013055555555555555"/>
      <inertia ixx="8.538442129629629e-07" ixy="0.00" ixz="0.00" iyy="9.61412199074074e-06" iyz="0.00" izz="1.0466203703703703e-05"/>
    </inertial>
    <visual>
      <origin rpy="0 0 0" xyz="0.0235 0 0"/>
      <geometry>
        <box size="0.047 0.028 0.0009"/>
      </geometry>
    </visual>
    <collision>
      <origin rpy="0 0 0" xyz="0.0235 0 0"/>
      <geometry>
        <box size="0.047 0.028 0.0009"/>
      </geometry>
    </collision>
  </link>
  <gazebo reference="finger_2_segment_link_4">
    <material>Gazebo/Orange</material>
    <mu1>0.1</mu1>
    <mu2>0.1</mu2>
    <maxVel>0.0</maxVel>
    <minDepth>0.001</minDepth>
    <!-- <kp>100</kp>
        <kd>1</kd> -->
  </gazebo>
  <!-- bending joint -->
  <joint name="finger_2_segment_joint_3" type="revolute">
    <axis rpy="0 0 0" xyz="0 1 0"/>
    <parent link="finger_2_segment_link_3"/>
    <child link="finger_2_segment_link_4"/>
    <origin rpy="0 0 0" xyz="0.047 0 0"/>
    <limit effort="1000.0" lower="-1.0" upper="1.0" velocity="1.0"/>
    <dynamics damping="0.01" friction="0.0"/>
  </joint>
  <gazebo reference="finger_2_segment_joint_3">
    <provideFeedback>1</provideFeedback>
    <springReference>0.0</springReference>
    <implicitSpringDamper>1</implicitSpringDamper>
    <springStiffness>3.0</springStiffness>
  </gazebo>
  <!-- set transmission for gazebo ROS controllers-->
  <transmission name="finger_2_segment_tran_3">
    <type>transmission_interface/SimpleTransmission</type>
    <joint name="finger_2_segment_joint_3">
      <hardwareInterface>hardware_interface/EffortJointInterface</hardwareInterface>
    </joint>
    <actuator name="finger_2_segment_motor_3">
      <hardwareInterface>hardware_interface/EffortJointInterface</hardwareInterface>
      <mechanicalReduction>1</mechanicalReduction>
    </actuator>
  </transmission>
  <link name="finger_2_segment_link_5">
    <inertial>
      <mass value="0.013055555555555555"/>
      <inertia ixx="8.538442129629629e-07" ixy="0.00" ixz="0.00" iyy="9.61412199074074e-06" iyz="0.00" izz="1.0466203703703703e-05"/>
    </inertial>
    <visual>
      <origin rpy="0 0 0" xyz="0.0235 0 0"/>
      <geometry>
        <box size="0.047 0.028 0.0009"/>
      </geometry>
    </visual>
    <collision>
      <origin rpy="0 0 0" xyz="0.0235 0 0"/>
      <geometry>
        <box size="0.047 0.028 0.0009"/>
      </geometry>
    </collision>
  </link>
  <gazebo reference="finger_2_segment_link_5">
    <material>Gazebo/Orange</material>
    <mu1>0.1</mu1>
    <mu2>0.1</mu2>
    <maxVel>0.0</maxVel>
    <minDepth>0.001</minDepth>
    <!-- <kp>100</kp>
        <kd>1</kd> -->
  </gazebo>
  <!-- bending joint -->
  <joint name="finger_2_segment_joint_4" type="revolute">
    <axis rpy="0 0 0" xyz="0 1 0"/>
    <parent link="finger_2_segment_link_4"/>
    <child link="finger_2_segment_link_5"/>
    <origin rpy="0 0 0" xyz="0.047 0 0"/>
    <limit effort="1000.0" lower="-1.0" upper="1.0" velocity="1.0"/>
    <dynamics damping="0.01" friction="0.0"/>
  </joint>
  <gazebo reference="finger_2_segment_joint_4">
    <provideFeedback>1</provideFeedback>
    <springReference>0.0</springReference>
    <implicitSpringDamper>1</implicitSpringDamper>
    <springStiffness>3.0</springStiffness>
  </gazebo>
  <!-- set transmission for gazebo ROS controllers-->
  <transmission name="finger_2_segment_tran_4">
    <type>transmission_interface/SimpleTransmission</type>
    <joint name="finger_2_segment_joint_4">
      <hardwareInterface>hardware_interface/EffortJointInterface</hardwareInterface>
    </joint>
    <actuator name="finger_2_segment_motor_4">
      <hardwareInterface>hardware_interface/EffortJointInterface</hardwareInterface>
      <mechanicalReduction>1</mechanicalReduction>
    </actuator>
  </transmission>
  <!-- Add the finger hook link -->
  <link name="finger_2_finger_hook_link">
    <inertial>
      <mass value="0.009722222222222222"/>
      <inertia ixx="6.358414351851852e-07" ixy="0.00" ixz="0.00" iyy="3.970563657407408e-06" iyz="0.00" izz="4.605092592592593e-06"/>
    </inertial>
    <visual>
      <origin rpy="0 0 0" xyz="0.0175 0 0"/>
      <geometry>
        <box size="0.035 0.028 0.0009"/>
      </geometry>
    </visual>
    <collision>
      <origin rpy="0 0 0" xyz="0.0175 0 0"/>
      <geometry>
        <box size="0.035 0.028 0.0009"/>
      </geometry>
    </collision>
  </link>
  <gazebo reference="finger_2_finger_hook_link">
    <material>Gazebo/Orange</material>
    <mu1>0.1</mu1>
    <mu2>0.1</mu2>
    <maxVel>0.0</maxVel>
    <minDepth>0.001</minDepth>
    <!-- <kp>100</kp>
        <kd>1</kd> -->
  </gazebo>
  <joint name="finger_2_finger_hook_joint" type="fixed">
    <parent link="finger_2_segment_link_5"/>
    <child link="finger_2_finger_hook_link"/>
    <origin rpy="0 -1.5707963267948502 0" xyz="0.047 0 0"/>
  </joint>
  <!-- PARAMETERS TO BE SET BY HAND -->
  <!-- END OF PARAMETERS TO BE SET BY HAND -->
  <joint name="finger_3_segment_joint_0" type="revolute">
    <origin rpy="1.5707963267948966 0 0" xyz="0.129 -0.007 0"/>
    <parent link="finger_3"/>
    <child link="finger_3_segment_link_1"/>
    <axis rpy="0 0 0" xyz="0 1 0"/>
    <limit effort="1000.0" lower="-1.0" upper="1.0" velocity="1.0"/>
    <dynamics damping="0.01" friction="0.0"/>
  </joint>
  <!-- END TESTING OF BASE JOINT (rather than fixed) -->
  <link name="finger_3_segment_link_1">
    <inertial>
      <mass value="0.013055555555555555"/>
      <inertia ixx="8.538442129629629e-07" ixy="0.00" ixz="0.00" iyy="9.61412199074074e-06" iyz="0.00" izz="1.0466203703703703e-05"/>
    </inertial>
    <visual>
      <origin rpy="0 0 0" xyz="0.0235 0 0"/>
      <geometry>
        <box size="0.047 0.028 0.0009"/>
      </geometry>
    </visual>
    <collision>
      <origin rpy="0 0 0" xyz="0.0235 0 0"/>
      <geometry>
        <box size="0.047 0.028 0.0009"/>
      </geometry>
    </collision>
  </link>
  <gazebo reference="finger_3_segment_link_1">
    <material>Gazebo/Orange</material>
    <mu1>0.1</mu1>
    <mu2>0.1</mu2>
    <maxVel>0.0</maxVel>
    <minDepth>0.001</minDepth>
    <!-- <kp>100</kp>
        <kd>1</kd> -->
  </gazebo>
  <link name="finger_3_segment_link_2">
    <inertial>
      <mass value="0.013055555555555555"/>
      <inertia ixx="8.538442129629629e-07" ixy="0.00" ixz="0.00" iyy="9.61412199074074e-06" iyz="0.00" izz="1.0466203703703703e-05"/>
    </inertial>
    <visual>
      <origin rpy="0 0 0" xyz="0.0235 0 0"/>
      <geometry>
        <box size="0.047 0.028 0.0009"/>
      </geometry>
    </visual>
    <collision>
      <origin rpy="0 0 0" xyz="0.0235 0 0"/>
      <geometry>
        <box size="0.047 0.028 0.0009"/>
      </geometry>
    </collision>
  </link>
  <gazebo reference="finger_3_segment_link_2">
    <material>Gazebo/Orange</material>
    <mu1>0.1</mu1>
    <mu2>0.1</mu2>
    <maxVel>0.0</maxVel>
    <minDepth>0.001</minDepth>
    <!-- <kp>100</kp>
        <kd>1</kd> -->
  </gazebo>
  <!-- bending joint -->
  <joint name="finger_3_segment_joint_1" type="revolute">
    <axis rpy="0 0 0" xyz="0 1 0"/>
    <parent link="finger_3_segment_link_1"/>
    <child link="finger_3_segment_link_2"/>
    <origin rpy="0 0 0" xyz="0.047 0 0"/>
    <limit effort="1000.0" lower="-1.0" upper="1.0" velocity="1.0"/>
    <dynamics damping="0.01" friction="0.0"/>
  </joint>
  <gazebo reference="finger_3_segment_joint_1">
    <provideFeedback>1</provideFeedback>
    <springReference>0.0</springReference>
    <implicitSpringDamper>1</implicitSpringDamper>
    <springStiffness>3.0</springStiffness>
  </gazebo>
  <!-- set transmission for gazebo ROS controllers-->
  <transmission name="finger_3_segment_tran_1">
    <type>transmission_interface/SimpleTransmission</type>
    <joint name="finger_3_segment_joint_1">
      <hardwareInterface>hardware_interface/EffortJointInterface</hardwareInterface>
    </joint>
    <actuator name="finger_3_segment_motor_1">
      <hardwareInterface>hardware_interface/EffortJointInterface</hardwareInterface>
      <mechanicalReduction>1</mechanicalReduction>
    </actuator>
  </transmission>
  <link name="finger_3_segment_link_3">
    <inertial>
      <mass value="0.013055555555555555"/>
      <inertia ixx="8.538442129629629e-07" ixy="0.00" ixz="0.00" iyy="9.61412199074074e-06" iyz="0.00" izz="1.0466203703703703e-05"/>
    </inertial>
    <visual>
      <origin rpy="0 0 0" xyz="0.0235 0 0"/>
      <geometry>
        <box size="0.047 0.028 0.0009"/>
      </geometry>
    </visual>
    <collision>
      <origin rpy="0 0 0" xyz="0.0235 0 0"/>
      <geometry>
        <box size="0.047 0.028 0.0009"/>
      </geometry>
    </collision>
  </link>
  <gazebo reference="finger_3_segment_link_3">
    <material>Gazebo/Orange</material>
    <mu1>0.1</mu1>
    <mu2>0.1</mu2>
    <maxVel>0.0</maxVel>
    <minDepth>0.001</minDepth>
    <!-- <kp>100</kp>
        <kd>1</kd> -->
  </gazebo>
  <!-- bending joint -->
  <joint name="finger_3_segment_joint_2" type="revolute">
    <axis rpy="0 0 0" xyz="0 1 0"/>
    <parent link="finger_3_segment_link_2"/>
    <child link="finger_3_segment_link_3"/>
    <origin rpy="0 0 0" xyz="0.047 0 0"/>
    <limit effort="1000.0" lower="-1.0" upper="1.0" velocity="1.0"/>
    <dynamics damping="0.01" friction="0.0"/>
  </joint>
  <gazebo reference="finger_3_segment_joint_2">
    <provideFeedback>1</provideFeedback>
    <springReference>0.0</springReference>
    <implicitSpringDamper>1</implicitSpringDamper>
    <springStiffness>3.0</springStiffness>
  </gazebo>
  <!-- set transmission for gazebo ROS controllers-->
  <transmission name="finger_3_segment_tran_2">
    <type>transmission_interface/SimpleTransmission</type>
    <joint name="finger_3_segment_joint_2">
      <hardwareInterface>hardware_interface/EffortJointInterface</hardwareInterface>
    </joint>
    <actuator name="finger_3_segment_motor_2">
      <hardwareInterface>hardware_interface/EffortJointInterface</hardwareInterface>
      <mechanicalReduction>1</mechanicalReduction>
    </actuator>
  </transmission>
  <link name="finger_3_segment_link_4">
    <inertial>
      <mass value="0.013055555555555555"/>
      <inertia ixx="8.538442129629629e-07" ixy="0.00" ixz="0.00" iyy="9.61412199074074e-06" iyz="0.00" izz="1.0466203703703703e-05"/>
    </inertial>
    <visual>
      <origin rpy="0 0 0" xyz="0.0235 0 0"/>
      <geometry>
        <box size="0.047 0.028 0.0009"/>
      </geometry>
    </visual>
    <collision>
      <origin rpy="0 0 0" xyz="0.0235 0 0"/>
      <geometry>
        <box size="0.047 0.028 0.0009"/>
      </geometry>
    </collision>
  </link>
  <gazebo reference="finger_3_segment_link_4">
    <material>Gazebo/Orange</material>
    <mu1>0.1</mu1>
    <mu2>0.1</mu2>
    <maxVel>0.0</maxVel>
    <minDepth>0.001</minDepth>
    <!-- <kp>100</kp>
        <kd>1</kd> -->
  </gazebo>
  <!-- bending joint -->
  <joint name="finger_3_segment_joint_3" type="revolute">
    <axis rpy="0 0 0" xyz="0 1 0"/>
    <parent link="finger_3_segment_link_3"/>
    <child link="finger_3_segment_link_4"/>
    <origin rpy="0 0 0" xyz="0.047 0 0"/>
    <limit effort="1000.0" lower="-1.0" upper="1.0" velocity="1.0"/>
    <dynamics damping="0.01" friction="0.0"/>
  </joint>
  <gazebo reference="finger_3_segment_joint_3">
    <provideFeedback>1</provideFeedback>
    <springReference>0.0</springReference>
    <implicitSpringDamper>1</implicitSpringDamper>
    <springStiffness>3.0</springStiffness>
  </gazebo>
  <!-- set transmission for gazebo ROS controllers-->
  <transmission name="finger_3_segment_tran_3">
    <type>transmission_interface/SimpleTransmission</type>
    <joint name="finger_3_segment_joint_3">
      <hardwareInterface>hardware_interface/EffortJointInterface</hardwareInterface>
    </joint>
    <actuator name="finger_3_segment_motor_3">
      <hardwareInterface>hardware_interface/EffortJointInterface</hardwareInterface>
      <mechanicalReduction>1</mechanicalReduction>
    </actuator>
  </transmission>
  <link name="finger_3_segment_link_5">
    <inertial>
      <mass value="0.013055555555555555"/>
      <inertia ixx="8.538442129629629e-07" ixy="0.00" ixz="0.00" iyy="9.61412199074074e-06" iyz="0.00" izz="1.0466203703703703e-05"/>
    </inertial>
    <visual>
      <origin rpy="0 0 0" xyz="0.0235 0 0"/>
      <geometry>
        <box size="0.047 0.028 0.0009"/>
      </geometry>
    </visual>
    <collision>
      <origin rpy="0 0 0" xyz="0.0235 0 0"/>
      <geometry>
        <box size="0.047 0.028 0.0009"/>
      </geometry>
    </collision>
  </link>
  <gazebo reference="finger_3_segment_link_5">
    <material>Gazebo/Orange</material>
    <mu1>0.1</mu1>
    <mu2>0.1</mu2>
    <maxVel>0.0</maxVel>
    <minDepth>0.001</minDepth>
    <!-- <kp>100</kp>
        <kd>1</kd> -->
  </gazebo>
  <!-- bending joint -->
  <joint name="finger_3_segment_joint_4" type="revolute">
    <axis rpy="0 0 0" xyz="0 1 0"/>
    <parent link="finger_3_segment_link_4"/>
    <child link="finger_3_segment_link_5"/>
    <origin rpy="0 0 0" xyz="0.047 0 0"/>
    <limit effort="1000.0" lower="-1.0" upper="1.0" velocity="1.0"/>
    <dynamics damping="0.01" friction="0.0"/>
  </joint>
  <gazebo reference="finger_3_segment_joint_4">
    <provideFeedback>1</provideFeedback>
    <springReference>0.0</springReference>
    <implicitSpringDamper>1</implicitSpringDamper>
    <springStiffness>3.0</springStiffness>
  </gazebo>
  <!-- set transmission for gazebo ROS controllers-->
  <transmission name="finger_3_segment_tran_4">
    <type>transmission_interface/SimpleTransmission</type>
    <joint name="finger_3_segment_joint_4">
      <hardwareInterface>hardware_interface/EffortJointInterface</hardwareInterface>
    </joint>
    <actuator name="finger_3_segment_motor_4">
      <hardwareInterface>hardware_interface/EffortJointInterface</hardwareInterface>
      <mechanicalReduction>1</mechanicalReduction>
    </actuator>
  </transmission>
  <!-- Add the finger hook link -->
  <link name="finger_3_finger_hook_link">
    <inertial>
      <mass value="0.009722222222222222"/>
      <inertia ixx="6.358414351851852e-07" ixy="0.00" ixz="0.00" iyy="3.970563657407408e-06" iyz="0.00" izz="4.605092592592593e-06"/>
    </inertial>
    <visual>
      <origin rpy="0 0 0" xyz="0.0175 0 0"/>
      <geometry>
        <box size="0.035 0.028 0.0009"/>
      </geometry>
    </visual>
    <collision>
      <origin rpy="0 0 0" xyz="0.0175 0 0"/>
      <geometry>
        <box size="0.035 0.028 0.0009"/>
      </geometry>
    </collision>
  </link>
  <gazebo reference="finger_3_finger_hook_link">
    <material>Gazebo/Orange</material>
    <mu1>0.1</mu1>
    <mu2>0.1</mu2>
    <maxVel>0.0</maxVel>
    <minDepth>0.001</minDepth>
    <!-- <kp>100</kp>
        <kd>1</kd> -->
  </gazebo>
  <joint name="finger_3_finger_hook_joint" type="fixed">
    <parent link="finger_3_segment_link_5"/>
    <child link="finger_3_finger_hook_link"/>
    <origin rpy="0 -1.5707963267948502 0" xyz="0.047 0 0"/>
  </joint>
  <gazebo>
    <plugin filename="libfinger_controller_plugin.so" name="finger_controller_plugin"/>
  </gazebo>
  <!-- attach gripper to the ground for gazebo -->
  <link name="world"/>
  <joint name="world_to_base" type="fixed">
    <origin rpy="3.141592653589793 0 0" xyz="0 0 1"/>
    <parent link="world"/>
    <child link="gripper_base_link"/>
  </joint>
</robot>

