<sdf version='1.7'>
  <model name='panda_and_gripper'>
    <joint name='world_to_base' type='fixed'>
      <pose relative_to='__model__'>0 0 0 0 -0 0</pose>
      <parent>world</parent>
      <child>panda_link0</child>
    </joint>
    <link name='panda_link0'>
      <pose relative_to='world_to_base'>0 0 0 0 -0 0</pose>
      <inertial>
        <pose>0 0 0 0 -0 0</pose>
        <mass>3.06</mass>
        <inertia>
          <ixx>0.3</ixx>
          <ixy>0</ixy>
          <ixz>0</ixz>
          <iyy>0.3</iyy>
          <iyz>0</iyz>
          <izz>0.3</izz>
        </inertia>
      </inertial>
      <collision name='panda_link0_collision'>
        <pose>0 0 0 0 -0 0</pose>
        <geometry>
          <mesh>
            <scale>1 1 1</scale>
            <uri>model://gripper_description/meshes_panda/panda collision link0.stl</uri>
          </mesh>
        </geometry>
        <surface>
          <contact>
            <ode/>
          </contact>
          <friction>
            <ode>
              <mu>0.2</mu>
              <mu2>0.2</mu2>
            </ode>
          </friction>
        </surface>
      </collision>
      <visual name='panda_link0_visual'>
        <pose>0 0 0 0 -0 0</pose>
        <geometry>
          <mesh>
            <scale>1 1 1</scale>
            <uri>model://gripper_description/meshes_panda/panda visual link0.stl</uri>
          </mesh>
        </geometry>
        <material>
          <script>
            <name>Gazebo/White</name>
            <uri>file://media/materials/scripts/gazebo.material</uri>
          </script>
        </material>
      </visual>
    </link>
    <joint name='panda_joint1' type='revolute'>
      <pose relative_to='panda_link0'>0 0 0.333 0 -0 0</pose>
      <parent>panda_link0</parent>
      <child>panda_link1</child>
      <axis>
        <xyz>0 0 1</xyz>
        <limit>
          <lower>-2.8973</lower>
          <upper>2.8973</upper>
          <effort>87</effort>
          <velocity>2.175</velocity>
        </limit>
        <dynamics>
          <damping>1</damping>
          <friction>0.1</friction>
          <spring_reference>0</spring_reference>
          <spring_stiffness>0</spring_stiffness>
        </dynamics>
      </axis>
    </joint>
    <link name='panda_link1'>
      <pose relative_to='panda_joint1'>0 0 0 0 -0 0</pose>
      <inertial>
        <pose>0 0 0 0 -0 0</pose>
        <mass>2.34</mass>
        <inertia>
          <ixx>0.70337</ixx>
          <ixy>-0.000139</ixy>
          <ixz>0.006772</ixz>
          <iyy>0.70661</iyy>
          <iyz>0.019169</iyz>
          <izz>0.009117</izz>
        </inertia>
      </inertial>
      <collision name='panda_link1_collision'>
        <pose>0 0 0 0 -0 0</pose>
        <geometry>
          <mesh>
            <scale>1 1 1</scale>
            <uri>model://gripper_description/meshes_panda/panda collision link1.stl</uri>
          </mesh>
        </geometry>
        <surface>
          <contact>
            <ode/>
          </contact>
          <friction>
            <ode>
              <mu>0.2</mu>
              <mu2>0.2</mu2>
            </ode>
          </friction>
        </surface>
      </collision>
      <visual name='panda_link1_visual'>
        <pose>0 0 0 0 -0 0</pose>
        <geometry>
          <mesh>
            <scale>1 1 1</scale>
            <uri>model://gripper_description/meshes_panda/panda visual link1.stl</uri>
          </mesh>
        </geometry>
        <material>
          <script>
            <name>Gazebo/White</name>
            <uri>file://media/materials/scripts/gazebo.material</uri>
          </script>
        </material>
      </visual>
    </link>
    <joint name='panda_joint2' type='revolute'>
      <pose relative_to='panda_link1'>0 0 0 -1.5708 0 0</pose>
      <parent>panda_link1</parent>
      <child>panda_link2</child>
      <axis>
        <xyz>0 0 1</xyz>
        <limit>
          <lower>-1.7628</lower>
          <upper>1.7628</upper>
          <effort>87</effort>
          <velocity>2.175</velocity>
        </limit>
        <dynamics>
          <damping>1</damping>
          <friction>0.1</friction>
          <spring_reference>0</spring_reference>
          <spring_stiffness>0</spring_stiffness>
        </dynamics>
      </axis>
    </joint>
    <link name='panda_link2'>
      <pose relative_to='panda_joint2'>0 0 0 0 -0 0</pose>
      <inertial>
        <pose>0 0 0 0 -0 0</pose>
        <mass>2.36</mass>
        <inertia>
          <ixx>0.007962</ixx>
          <ixy>-0.003925</ixy>
          <ixz>0.010254</ixz>
          <iyy>0.02811</iyy>
          <iyz>0.000704</iyz>
          <izz>0.025995</izz>
        </inertia>
      </inertial>
      <collision name='panda_link2_collision'>
        <pose>0 0 0 0 -0 0</pose>
        <geometry>
          <mesh>
            <scale>1 1 1</scale>
            <uri>model://gripper_description/meshes_panda/panda collision link2.stl</uri>
          </mesh>
        </geometry>
        <surface>
          <contact>
            <ode/>
          </contact>
          <friction>
            <ode>
              <mu>0.2</mu>
              <mu2>0.2</mu2>
            </ode>
          </friction>
        </surface>
      </collision>
      <visual name='panda_link2_visual'>
        <pose>0 0 0 0 -0 0</pose>
        <geometry>
          <mesh>
            <scale>1 1 1</scale>
            <uri>model://gripper_description/meshes_panda/panda visual link2.stl</uri>
          </mesh>
        </geometry>
        <material>
          <script>
            <name>Gazebo/White</name>
            <uri>file://media/materials/scripts/gazebo.material</uri>
          </script>
        </material>
      </visual>
    </link>
    <joint name='panda_joint3' type='revolute'>
      <pose relative_to='panda_link2'>0 -0.316 0 1.5708 -0 0</pose>
      <parent>panda_link2</parent>
      <child>panda_link3</child>
      <axis>
        <xyz>0 0 1</xyz>
        <limit>
          <lower>-2.8973</lower>
          <upper>2.8973</upper>
          <effort>87</effort>
          <velocity>2.175</velocity>
        </limit>
        <dynamics>
          <damping>1</damping>
          <friction>0.1</friction>
          <spring_reference>0</spring_reference>
          <spring_stiffness>0</spring_stiffness>
        </dynamics>
      </axis>
    </joint>
    <link name='panda_link3'>
      <pose relative_to='panda_joint3'>0 0 0 0 -0 0</pose>
      <inertial>
        <pose>0 0 0 0 -0 0</pose>
        <mass>2.38</mass>
        <inertia>
          <ixx>0.037242</ixx>
          <ixy>-0.004761</ixy>
          <ixz>-0.011396</ixz>
          <iyy>0.036155</iyy>
          <iyz>-0.012805</iyz>
          <izz>0.01083</izz>
        </inertia>
      </inertial>
      <collision name='panda_link3_collision'>
        <pose>0 0 0 0 -0 0</pose>
        <geometry>
          <mesh>
            <scale>1 1 1</scale>
            <uri>model://gripper_description/meshes_panda/panda collision link3.stl</uri>
          </mesh>
        </geometry>
        <surface>
          <contact>
            <ode/>
          </contact>
          <friction>
            <ode>
              <mu>0.2</mu>
              <mu2>0.2</mu2>
            </ode>
          </friction>
        </surface>
      </collision>
      <visual name='panda_link3_visual'>
        <pose>0 0 0 0 -0 0</pose>
        <geometry>
          <mesh>
            <scale>1 1 1</scale>
            <uri>model://gripper_description/meshes_panda/panda visual link3.stl</uri>
          </mesh>
        </geometry>
        <material>
          <script>
            <name>Gazebo/White</name>
            <uri>file://media/materials/scripts/gazebo.material</uri>
          </script>
        </material>
      </visual>
    </link>
    <joint name='panda_joint4' type='revolute'>
      <pose relative_to='panda_link3'>0.0825 0 0 1.5708 -0 0</pose>
      <parent>panda_link3</parent>
      <child>panda_link4</child>
      <axis>
        <xyz>0 0 1</xyz>
        <limit>
          <lower>-3.0718</lower>
          <upper>-0.0698</upper>
          <effort>87</effort>
          <velocity>2.175</velocity>
        </limit>
        <dynamics>
          <damping>1</damping>
          <friction>0.1</friction>
          <spring_reference>0</spring_reference>
          <spring_stiffness>0</spring_stiffness>
        </dynamics>
      </axis>
    </joint>
    <link name='panda_link4'>
      <pose relative_to='panda_joint4'>0 0 0 0 -0 0</pose>
      <inertial>
        <pose>0 0 0 0 -0 0</pose>
        <mass>2.43</mass>
        <inertia>
          <ixx>0.025853</ixx>
          <ixy>0.007796</ixy>
          <ixz>-0.001332</ixz>
          <iyy>0.019552</iyy>
          <iyz>0.008641</iyz>
          <izz>0.028323</izz>
        </inertia>
      </inertial>
      <collision name='panda_link4_collision'>
        <pose>0 0 0 0 -0 0</pose>
        <geometry>
          <mesh>
            <scale>1 1 1</scale>
            <uri>model://gripper_description/meshes_panda/panda collision link4.stl</uri>
          </mesh>
        </geometry>
        <surface>
          <contact>
            <ode/>
          </contact>
          <friction>
            <ode>
              <mu>0.2</mu>
              <mu2>0.2</mu2>
            </ode>
          </friction>
        </surface>
      </collision>
      <visual name='panda_link4_visual'>
        <pose>0 0 0 0 -0 0</pose>
        <geometry>
          <mesh>
            <scale>1 1 1</scale>
            <uri>model://gripper_description/meshes_panda/panda visual link4.stl</uri>
          </mesh>
        </geometry>
        <material>
          <script>
            <name>Gazebo/White</name>
            <uri>file://media/materials/scripts/gazebo.material</uri>
          </script>
        </material>
      </visual>
    </link>
    <joint name='panda_joint5' type='revolute'>
      <pose relative_to='panda_link4'>-0.0825 0.384 0 -1.5708 0 0</pose>
      <parent>panda_link4</parent>
      <child>panda_link5</child>
      <axis>
        <xyz>0 0 1</xyz>
        <limit>
          <lower>-2.8973</lower>
          <upper>2.8973</upper>
          <effort>12</effort>
          <velocity>2.61</velocity>
        </limit>
        <dynamics>
          <damping>1</damping>
          <friction>0.1</friction>
          <spring_reference>0</spring_reference>
          <spring_stiffness>0</spring_stiffness>
        </dynamics>
      </axis>
    </joint>
    <link name='panda_link5'>
      <pose relative_to='panda_joint5'>0 0 0 0 -0 0</pose>
      <inertial>
        <pose>0 0 0 0 -0 0</pose>
        <mass>3.5</mass>
        <inertia>
          <ixx>0.035549</ixx>
          <ixy>-0.002117</ixy>
          <ixz>-0.004037</ixz>
          <iyy>0.029474</iyy>
          <iyz>0.000229</iyz>
          <izz>0.008627</izz>
        </inertia>
      </inertial>
      <collision name='panda_link5_collision'>
        <pose>0 0 0 0 -0 0</pose>
        <geometry>
          <mesh>
            <scale>1 1 1</scale>
            <uri>model://gripper_description/meshes_panda/panda collision link5.stl</uri>
          </mesh>
        </geometry>
        <surface>
          <contact>
            <ode/>
          </contact>
          <friction>
            <ode>
              <mu>0.2</mu>
              <mu2>0.2</mu2>
            </ode>
          </friction>
        </surface>
      </collision>
      <visual name='panda_link5_visual'>
        <pose>0 0 0 0 -0 0</pose>
        <geometry>
          <mesh>
            <scale>1 1 1</scale>
            <uri>model://gripper_description/meshes_panda/panda visual link5.stl</uri>
          </mesh>
        </geometry>
        <material>
          <script>
            <name>Gazebo/White</name>
            <uri>file://media/materials/scripts/gazebo.material</uri>
          </script>
        </material>
      </visual>
    </link>
    <joint name='panda_joint6' type='revolute'>
      <pose relative_to='panda_link5'>0 0 0 1.5708 -0 0</pose>
      <parent>panda_link5</parent>
      <child>panda_link6</child>
      <axis>
        <xyz>0 0 1</xyz>
        <limit>
          <lower>-0.0175</lower>
          <upper>3.7525</upper>
          <effort>12</effort>
          <velocity>2.61</velocity>
        </limit>
        <dynamics>
          <damping>1</damping>
          <friction>0.1</friction>
          <spring_reference>0</spring_reference>
          <spring_stiffness>0</spring_stiffness>
        </dynamics>
      </axis>
    </joint>
    <link name='panda_link6'>
      <pose relative_to='panda_joint6'>0 0 0 0 -0 0</pose>
      <inertial>
        <pose>0 0 0 0 -0 0</pose>
        <mass>1.47</mass>
        <inertia>
          <ixx>0.001964</ixx>
          <ixy>0.000109</ixy>
          <ixz>-0.001158</ixz>
          <iyy>0.004354</iyy>
          <iyz>0.000341</iyz>
          <izz>0.005433</izz>
        </inertia>
      </inertial>
      <collision name='panda_link6_collision'>
        <pose>0 0 0 0 -0 0</pose>
        <geometry>
          <mesh>
            <scale>1 1 1</scale>
            <uri>model://gripper_description/meshes_panda/panda collision link6.stl</uri>
          </mesh>
        </geometry>
        <surface>
          <contact>
            <ode/>
          </contact>
          <friction>
            <ode>
              <mu>0.2</mu>
              <mu2>0.2</mu2>
            </ode>
          </friction>
        </surface>
      </collision>
      <visual name='panda_link6_visual'>
        <pose>0 0 0 0 -0 0</pose>
        <geometry>
          <mesh>
            <scale>1 1 1</scale>
            <uri>model://gripper_description/meshes_panda/panda visual link6.stl</uri>
          </mesh>
        </geometry>
        <material>
          <script>
            <name>Gazebo/White</name>
            <uri>file://media/materials/scripts/gazebo.material</uri>
          </script>
        </material>
      </visual>
    </link>
    <joint name='panda_joint7' type='revolute'>
      <pose relative_to='panda_link6'>0.088 0 0 1.5708 -0 0</pose>
      <parent>panda_link6</parent>
      <child>panda_link7</child>
      <axis>
        <xyz>0 0 1</xyz>
        <limit>
          <lower>-2.8973</lower>
          <upper>2.8973</upper>
          <effort>12</effort>
          <velocity>2.61</velocity>
        </limit>
        <dynamics>
          <damping>1</damping>
          <friction>0.1</friction>
          <spring_reference>0</spring_reference>
          <spring_stiffness>0</spring_stiffness>
        </dynamics>
      </axis>
    </joint>
    <link name='panda_link7'>
      <pose relative_to='panda_joint7'>0 0 0 0 -0 0</pose>
      <inertial>
        <pose>0 0 0.211538 0 -0 0</pose>
        <mass>1.95</mass>
        <inertia>
          <ixx>0.0488062</ixx>
          <ixy>-0.000363</ixy>
          <ixz>-0.00110005</ixz>
          <iyy>0.0463226</iyy>
          <iyz>-0.000665297</iyz>
          <izz>0.010045</izz>
        </inertia>
      </inertial>
      <collision name='panda_link7_collision'>
        <pose>0 0 0 0 -0 0</pose>
        <geometry>
          <mesh>
            <scale>1 1 1</scale>
            <uri>model://gripper_description/meshes_panda/panda collision link7.stl</uri>
          </mesh>
        </geometry>
      </collision>
      <collision name='panda_link7_fixed_joint_lump__gripper_base_link_collision_1'>
        <pose>0 0 0.25 0 0 -0.785398</pose>
        <geometry>
          <cylinder>
            <length>0.1</length>
            <radius>0.03</radius>
          </cylinder>
        </geometry>
        <surface>
          <contact>
            <ode/>
          </contact>
          <friction>
            <ode>
              <mu>0.2</mu>
              <mu2>0.2</mu2>
            </ode>
          </friction>
        </surface>
      </collision>
      <visual name='panda_link7_visual'>
        <pose>0 0 0 0 -0 0</pose>
        <geometry>
          <mesh>
            <scale>1 1 1</scale>
            <uri>model://gripper_description/meshes_panda/panda visual link7.stl</uri>
          </mesh>
        </geometry>
      </visual>
      <visual name='panda_link7_fixed_joint_lump__gripper_base_link_visual_1'>
        <pose>0 0 0.25 0 0 -0.785398</pose>
        <geometry>
          <mesh>
            <scale>1 1 1</scale>
            <uri>model://gripper_description/meshes/main body visual.STL</uri>
          </mesh>
        </geometry>
        <material>
          <script>
            <name>Gazebo/Grey</name>
            <uri>file://media/materials/scripts/gazebo.material</uri>
          </script>
        </material>
      </visual>
    </link>
    <joint name='finger_1_prismatic_joint' type='prismatic'>
      <pose relative_to='panda_link7'>0 0 0.25 -0.785398 -1.5708 0</pose>
      <parent>panda_link7</parent>
      <child>finger_1_intermediate</child>
      <axis>
        <xyz>0 1 0</xyz>
        <limit>
          <lower>0.049</lower>
          <upper>0.134</upper>
          <effort>40</effort>
          <velocity>0.015</velocity>
        </limit>
        <dynamics>
          <damping>1</damping>
          <friction>0</friction>
          <spring_reference>0</spring_reference>
          <spring_stiffness>0</spring_stiffness>
        </dynamics>
      </axis>
    </joint>
    <link name='finger_1_intermediate'>
      <pose relative_to='finger_1_prismatic_joint'>0 0 0 0 -0 0</pose>
      <inertial>
        <pose>0 0 0 0 -0 0</pose>
        <mass>0.1</mass>
        <inertia>
          <ixx>5.559e-05</ixx>
          <ixy>-4.723e-05</ixy>
          <ixz>1.16e-06</ixz>
          <iyy>0.00014636</iyy>
          <iyz>1e-06</iyz>
          <izz>0.00015418</izz>
        </inertia>
      </inertial>
      <collision name='finger_1_intermediate_collision'>
        <pose>0 0 0 0 -0 0</pose>
        <geometry>
          <mesh>
            <scale>1 1 1</scale>
            <uri>model://gripper_description/meshes/nut collision.STL</uri>
          </mesh>
        </geometry>
        <surface>
          <contact>
            <ode/>
          </contact>
          <friction>
            <ode>
              <mu>0.2</mu>
              <mu2>0.2</mu2>
            </ode>
          </friction>
        </surface>
      </collision>
      <visual name='finger_1_intermediate_visual'>
        <pose>0 0 0 0 -0 0</pose>
        <geometry>
          <mesh>
            <scale>1 1 1</scale>
            <uri>model://gripper_description/meshes/nut visual.STL</uri>
          </mesh>
        </geometry>
        <material>
          <script>
            <name>Gazebo/Grey</name>
            <uri>file://media/materials/scripts/gazebo.material</uri>
          </script>
        </material>
      </visual>
    </link>
    <joint name='finger_1_revolute_joint' type='revolute'>
      <pose relative_to='finger_1_intermediate'>0 0 0 0 -0 0</pose>
      <parent>finger_1_intermediate</parent>
      <child>finger_1</child>
      <axis>
        <xyz>0 0 1</xyz>
        <limit>
          <lower>-0.7</lower>
          <upper>0.7</upper>
          <effort>40</effort>
          <velocity>0.1</velocity>
        </limit>
        <dynamics>
          <damping>1</damping>
          <friction>0</friction>
          <spring_reference>0</spring_reference>
          <spring_stiffness>0</spring_stiffness>
        </dynamics>
      </axis>
    </joint>
    <link name='finger_1'>
      <pose relative_to='finger_1_revolute_joint'>0 0 0 0 -0 0</pose>
      <inertial>
        <pose>0 0 0 0 -0 0</pose>
        <mass>0.2</mass>
        <inertia>
          <ixx>0.00028344</ixx>
          <ixy>-0.00056723</ixy>
          <ixz>-6.59e-06</ixz>
          <iyy>0.00138</iyy>
          <iyz>2.4e-06</iyz>
          <izz>0.0016</izz>
        </inertia>
      </inertial>
      <collision name='finger_1_collision'>
        <pose>0 0 0 0 -0 0</pose>
        <geometry>
          <mesh>
            <scale>1 1 1</scale>
            <uri>model://gripper_description/meshes/finger platform collision.STL</uri>
          </mesh>
        </geometry>
        <surface>
          <contact>
            <ode/>
          </contact>
          <friction>
            <ode>
              <mu>0.2</mu>
              <mu2>0.2</mu2>
            </ode>
          </friction>
        </surface>
      </collision>
      <visual name='finger_1_visual'>
        <pose>0 0 0 0 -0 0</pose>
        <geometry>
          <mesh>
            <scale>1 1 1</scale>
            <uri>model://gripper_description/meshes/finger platform visual.STL</uri>
          </mesh>
        </geometry>
        <material>
          <script>
            <name>Gazebo/Grey</name>
            <uri>file://media/materials/scripts/gazebo.material</uri>
          </script>
        </material>
      </visual>
    </link>
    <joint name='finger_2_prismatic_joint' type='prismatic'>
      <pose relative_to='panda_link7'>0 0 0.25 -2.87979 -1.5708 0</pose>
      <parent>panda_link7</parent>
      <child>finger_2_intermediate</child>
      <axis>
        <xyz>0 1 0</xyz>
        <limit>
          <lower>0.049</lower>
          <upper>0.134</upper>
          <effort>40</effort>
          <velocity>0.015</velocity>
        </limit>
        <dynamics>
          <damping>1</damping>
          <friction>0</friction>
          <spring_reference>0</spring_reference>
          <spring_stiffness>0</spring_stiffness>
        </dynamics>
      </axis>
    </joint>
    <link name='finger_2_intermediate'>
      <pose relative_to='finger_2_prismatic_joint'>0 0 0 0 -0 0</pose>
      <inertial>
        <pose>0 0 0 0 -0 0</pose>
        <mass>0.1</mass>
        <inertia>
          <ixx>5.559e-05</ixx>
          <ixy>-4.723e-05</ixy>
          <ixz>1.16e-06</ixz>
          <iyy>0.00014636</iyy>
          <iyz>1e-06</iyz>
          <izz>0.00015418</izz>
        </inertia>
      </inertial>
      <collision name='finger_2_intermediate_collision'>
        <pose>0 0 0 0 -0 0</pose>
        <geometry>
          <mesh>
            <scale>1 1 1</scale>
            <uri>model://gripper_description/meshes/nut collision.STL</uri>
          </mesh>
        </geometry>
        <surface>
          <contact>
            <ode/>
          </contact>
          <friction>
            <ode>
              <mu>0.2</mu>
              <mu2>0.2</mu2>
            </ode>
          </friction>
        </surface>
      </collision>
      <visual name='finger_2_intermediate_visual'>
        <pose>0 0 0 0 -0 0</pose>
        <geometry>
          <mesh>
            <scale>1 1 1</scale>
            <uri>model://gripper_description/meshes/nut visual.STL</uri>
          </mesh>
        </geometry>
        <material>
          <script>
            <name>Gazebo/Grey</name>
            <uri>file://media/materials/scripts/gazebo.material</uri>
          </script>
        </material>
      </visual>
    </link>
    <joint name='finger_2_revolute_joint' type='revolute'>
      <pose relative_to='finger_2_intermediate'>0 0 0 0 -0 0</pose>
      <parent>finger_2_intermediate</parent>
      <child>finger_2</child>
      <axis>
        <xyz>0 0 1</xyz>
        <limit>
          <lower>-0.7</lower>
          <upper>0.7</upper>
          <effort>40</effort>
          <velocity>0.1</velocity>
        </limit>
        <dynamics>
          <damping>1</damping>
          <friction>0</friction>
          <spring_reference>0</spring_reference>
          <spring_stiffness>0</spring_stiffness>
        </dynamics>
      </axis>
    </joint>
    <link name='finger_2'>
      <pose relative_to='finger_2_revolute_joint'>0 0 0 0 -0 0</pose>
      <inertial>
        <pose>0 0 0 0 -0 0</pose>
        <mass>0.2</mass>
        <inertia>
          <ixx>0.00028344</ixx>
          <ixy>-0.00056723</ixy>
          <ixz>-6.59e-06</ixz>
          <iyy>0.00138</iyy>
          <iyz>2.4e-06</iyz>
          <izz>0.0016</izz>
        </inertia>
      </inertial>
      <collision name='finger_2_collision'>
        <pose>0 0 0 0 -0 0</pose>
        <geometry>
          <mesh>
            <scale>1 1 1</scale>
            <uri>model://gripper_description/meshes/finger platform collision.STL</uri>
          </mesh>
        </geometry>
        <surface>
          <contact>
            <ode/>
          </contact>
          <friction>
            <ode>
              <mu>0.2</mu>
              <mu2>0.2</mu2>
            </ode>
          </friction>
        </surface>
      </collision>
      <visual name='finger_2_visual'>
        <pose>0 0 0 0 -0 0</pose>
        <geometry>
          <mesh>
            <scale>1 1 1</scale>
            <uri>model://gripper_description/meshes/finger platform visual.STL</uri>
          </mesh>
        </geometry>
        <material>
          <script>
            <name>Gazebo/Grey</name>
            <uri>file://media/materials/scripts/gazebo.material</uri>
          </script>
        </material>
      </visual>
    </link>
    <joint name='finger_3_prismatic_joint' type='prismatic'>
      <pose relative_to='panda_link7'>0 0 0.25 1.309 -1.5708 0</pose>
      <parent>panda_link7</parent>
      <child>finger_3_intermediate</child>
      <axis>
        <xyz>0 1 0</xyz>
        <limit>
          <lower>0.049</lower>
          <upper>0.134</upper>
          <effort>40</effort>
          <velocity>0.015</velocity>
        </limit>
        <dynamics>
          <damping>1</damping>
          <friction>0</friction>
          <spring_reference>0</spring_reference>
          <spring_stiffness>0</spring_stiffness>
        </dynamics>
      </axis>
    </joint>
    <link name='finger_3_intermediate'>
      <pose relative_to='finger_3_prismatic_joint'>0 0 0 0 -0 0</pose>
      <inertial>
        <pose>0 0 0 0 -0 0</pose>
        <mass>0.1</mass>
        <inertia>
          <ixx>5.559e-05</ixx>
          <ixy>-4.723e-05</ixy>
          <ixz>1.16e-06</ixz>
          <iyy>0.00014636</iyy>
          <iyz>1e-06</iyz>
          <izz>0.00015418</izz>
        </inertia>
      </inertial>
      <collision name='finger_3_intermediate_collision'>
        <pose>0 0 0 0 -0 0</pose>
        <geometry>
          <mesh>
            <scale>1 1 1</scale>
            <uri>model://gripper_description/meshes/nut collision.STL</uri>
          </mesh>
        </geometry>
        <surface>
          <contact>
            <ode/>
          </contact>
          <friction>
            <ode>
              <mu>0.2</mu>
              <mu2>0.2</mu2>
            </ode>
          </friction>
        </surface>
      </collision>
      <visual name='finger_3_intermediate_visual'>
        <pose>0 0 0 0 -0 0</pose>
        <geometry>
          <mesh>
            <scale>1 1 1</scale>
            <uri>model://gripper_description/meshes/nut visual.STL</uri>
          </mesh>
        </geometry>
        <material>
          <script>
            <name>Gazebo/Grey</name>
            <uri>file://media/materials/scripts/gazebo.material</uri>
          </script>
        </material>
      </visual>
    </link>
    <joint name='finger_3_revolute_joint' type='revolute'>
      <pose relative_to='finger_3_intermediate'>0 0 0 0 -0 0</pose>
      <parent>finger_3_intermediate</parent>
      <child>finger_3</child>
      <axis>
        <xyz>0 0 1</xyz>
        <limit>
          <lower>-0.7</lower>
          <upper>0.7</upper>
          <effort>40</effort>
          <velocity>0.1</velocity>
        </limit>
        <dynamics>
          <damping>1</damping>
          <friction>0</friction>
          <spring_reference>0</spring_reference>
          <spring_stiffness>0</spring_stiffness>
        </dynamics>
      </axis>
    </joint>
    <link name='finger_3'>
      <pose relative_to='finger_3_revolute_joint'>0 0 0 0 -0 0</pose>
      <inertial>
        <pose>0 0 0 0 -0 0</pose>
        <mass>0.2</mass>
        <inertia>
          <ixx>0.00028344</ixx>
          <ixy>-0.00056723</ixy>
          <ixz>-6.59e-06</ixz>
          <iyy>0.00138</iyy>
          <iyz>2.4e-06</iyz>
          <izz>0.0016</izz>
        </inertia>
      </inertial>
      <collision name='finger_3_collision'>
        <pose>0 0 0 0 -0 0</pose>
        <geometry>
          <mesh>
            <scale>1 1 1</scale>
            <uri>model://gripper_description/meshes/finger platform collision.STL</uri>
          </mesh>
        </geometry>
        <surface>
          <contact>
            <ode/>
          </contact>
          <friction>
            <ode>
              <mu>0.2</mu>
              <mu2>0.2</mu2>
            </ode>
          </friction>
        </surface>
      </collision>
      <visual name='finger_3_visual'>
        <pose>0 0 0 0 -0 0</pose>
        <geometry>
          <mesh>
            <scale>1 1 1</scale>
            <uri>model://gripper_description/meshes/finger platform visual.STL</uri>
          </mesh>
        </geometry>
        <material>
          <script>
            <name>Gazebo/Grey</name>
            <uri>file://media/materials/scripts/gazebo.material</uri>
          </script>
        </material>
      </visual>
    </link>
    <joint name='palm_prismatic_joint' type='prismatic'>
      <pose relative_to='panda_link7'>0 0 0.25 -0.785398 -1.5708 0</pose>
      <parent>panda_link7</parent>
      <child>palm</child>
      <axis>
        <xyz>1 0 0</xyz>
        <limit>
          <lower>0</lower>
          <upper>0.165</upper>
          <effort>40</effort>
          <velocity>0.036</velocity>
        </limit>
        <dynamics>
          <damping>1</damping>
          <friction>0</friction>
          <spring_reference>0</spring_reference>
          <spring_stiffness>0</spring_stiffness>
        </dynamics>
      </axis>
    </joint>
    <link name='palm'>
      <pose relative_to='palm_prismatic_joint'>0 0 0 0 -0 0</pose>
      <inertial>
        <pose>0 0 0 0 -0 0</pose>
        <mass>0.05</mass>
        <inertia>
          <ixx>1e-05</ixx>
          <ixy>0</ixy>
          <ixz>0</ixz>
          <iyy>1e-05</iyy>
          <iyz>0</iyz>
          <izz>1e-05</izz>
        </inertia>
      </inertial>
      <collision name='palm_collision'>
        <pose>0 0 0 0 -0 0</pose>
        <geometry>
          <mesh>
            <scale>1 1 1</scale>
            <uri>model://gripper_description/meshes/palm collision.STL</uri>
          </mesh>
        </geometry>
        <surface>
          <contact>
            <ode/>
          </contact>
          <friction>
            <ode>
              <mu>0.2</mu>
              <mu2>0.2</mu2>
            </ode>
          </friction>
        </surface>
      </collision>
      <visual name='palm_visual'>
        <pose>0 0 0 0 -0 0</pose>
        <geometry>
          <mesh>
            <scale>1 1 1</scale>
            <uri>model://gripper_description/meshes/palm visual.STL</uri>
          </mesh>
        </geometry>
        <material>
          <script>
            <name>Gazebo/Grey</name>
            <uri>file://media/materials/scripts/gazebo.material</uri>
          </script>
        </material>
      </visual>
    </link>
    <plugin name='gazebo_ros_control' filename='libgazebo_ros_control.so'/>
    <plugin name='reset_joints_plugin' filename='libreset_joints_plugin.so'/>
    <frame name='panda_joint8' attached_to='panda_link7'>
      <pose>0 0 0.107 0 -0 0</pose>
    </frame>
    <frame name='panda_link8' attached_to='panda_joint8'/>
    <frame name='panda_to_eef_base_joint' attached_to='panda_link7'>
      <pose>0 0 0.25 0 0 -0.785398</pose>
    </frame>
    <frame name='gripper_base_link' attached_to='panda_to_eef_base_joint'/>
  </model>
</sdf>
